<?xml version="1.0" encoding="utf-8"?>
<!-- This URDF was automatically created by SolidWorks to URDF Exporter! Originally created by Stephen Brawner (brawner@gmail.com)
     Commit Version: 1.5.1-0-g916b5db  Build Version: 1.5.7152.31018
     For more information, please see http://wiki.ros.org/sw_urdf_exporter -->
<robot name="omwr" xmlns:xacro="http://www.ros.org/wiki/xacro">

  <xacro:include filename="$(find model)/omwr/xacro/description.gazebo" />
  <xacro:include filename="$(find model)/omwr/xacro/controller.gazebo" />

  <link name="world"/>
  <joint name="world_joint" type="fixed">
     <parent link="world"/>
     <child link="base_link"/>
  </joint>

  <!-- <link name="dummy"/>
   <joint name="dummy_joint" type="fixed">
      <parent link="dummy"/>
      <child link="base_link"/>
  </joint> -->

  <link name="base_link">
    <inertial>
      <origin xyz="0.00065919 -0.00041722 0.015944" rpy="0 0 0" />
      <mass value="1.058" />
      <inertia
        ixx="0.00090263" ixy="3.4505E-06" ixz="-3.9005E-08"
        iyy="0.00084416" iyz="-4.4483E-07"
        izz="0.0016961" />
    </inertial>
    <visual>
      <origin xyz="0 0 0" rpy="0 0 0" />
      <geometry>
        <mesh filename="package://model/omwr/meshes/base_link.STL" />
      </geometry>
      <material name="">
        <color rgba="1 0 0 1" />
      </material>
    </visual>
    <collision>
      <origin xyz="0 0 0" rpy="0 0 0" />
      <geometry>
        <mesh filename="package://model/omwr/meshes/base_link.STL" />
      </geometry>
    </collision>
  </link>
  <link name="wheel_link_1">
    <inertial>
      <origin xyz="-7.0678E-08 -1.651E-08 0.00026816" rpy="0 0 0" />
      <mass value="0.022785" />
      <inertia
        ixx="8.1964E-07" ixy="-2.3341E-12" ixz="1.462E-11"
        iyy="8.1964E-07" iyz="-1.0941E-12"
        izz="1.3233E-06" />
    </inertial>
    <visual>
      <origin xyz="0 0 0" rpy="0 0 0" />
      <geometry>
        <mesh filename="package://model/omwr/meshes/wheel_link_1.STL" />
      </geometry>
      <material name="">
        <color rgba="0.29804 0.29804 0.29804 1" />
      </material>
    </visual>
    <collision>
      <origin xyz="0 0 0" rpy="0 0 0" />
      <geometry>
        <mesh filename="package://model/omwr/meshes/wheel_link_1.STL" />
      </geometry>
    </collision>
  </link>
  <joint name="wheel_joint_1" type="continuous">
    <origin xyz="0.078938 0 -0.0152" rpy="0 1.5708 0" />
    <parent link="base_link" />
    <child link="wheel_link_1" />
    <axis xyz="0 0 1" />
  </joint>
  <link name="wheel_link_2">
    <inertial>
      <origin xyz="1.651E-08 -7.0679E-08 0.00026816" rpy="0 0 0" />
      <mass value="0.022785" />
      <inertia
        ixx="8.1964E-07" ixy="2.3341E-12" ixz="1.0941E-12"
        iyy="8.1964E-07" iyz="1.462E-11"
        izz="1.3233E-06" />
    </inertial>
    <visual>
      <origin xyz="0 0 0" rpy="0 0 0" />
      <geometry>
        <mesh filename="package://model/omwr/meshes/wheel_link_2.STL" />
      </geometry>
      <material name="">
        <color rgba="0.77647 0.75686 0.73725 1" />
      </material>
    </visual>
    <collision>
      <origin xyz="0 0 0" rpy="0 0 0" />
      <geometry>
        <mesh filename="package://model/omwr/meshes/wheel_link_2.STL" />
      </geometry>
    </collision>
  </link>
  <joint name="wheel_joint_2" type="continuous">
    <origin xyz="0 0.078938 -0.0152" rpy="-1.5708 0 0" />
    <parent link="base_link" />
    <child link="wheel_link_2" />
    <axis xyz="0 0 1" />
  </joint>
  <link name="wheel_link_3">
    <inertial>
      <origin xyz="-7.0679E-08 -1.651E-08 0.00026816" rpy="0 0 0" />
      <mass value="0.022785" />
      <inertia
        ixx="8.1964E-07" ixy="-2.3341E-12" ixz="1.462E-11"
        iyy="8.1964E-07" iyz="-1.0941E-12"
        izz="1.3233E-06" />
    </inertial>
    <visual>
      <origin xyz="0 0 0" rpy="0 0 0" />
      <geometry>
        <mesh filename="package://model/omwr/meshes/wheel_link_3.STL" />
      </geometry>
      <material name="">
        <color rgba="0.77647 0.75686 0.73725 1" />
      </material>
    </visual>
    <collision>
      <origin xyz="0 0 0" rpy="0 0 0" />
      <geometry>
        <mesh filename="package://model/omwr/meshes/wheel_link_3.STL" />
      </geometry>
    </collision>
  </link>
  <joint name="wheel_joint_3" type="continuous">
    <origin xyz="-0.078938 0 -0.0152" rpy="3.1416 1.5708 0" />
    <parent link="base_link" />
    <child link="wheel_link_3" />
    <axis xyz="0 0 1" />
  </joint>
  <link name="wheel_link_4">
    <inertial>
      <origin xyz="-1.651E-08 7.0678E-08 0.00026816" rpy="0 0 0" />
      <mass value="0.022785" />
      <inertia
        ixx="8.1964E-07" ixy="2.3341E-12" ixz="-1.0941E-12"
        iyy="8.1964E-07" iyz="-1.462E-11"
        izz="1.3233E-06" />
    </inertial>
    <visual>
      <origin xyz="0 0 0" rpy="0 0 0" />
      <geometry>
        <mesh filename="package://model/omwr/meshes/wheel_link_4.STL" />
      </geometry>
      <material name="">
        <color rgba="0.77647 0.75686 0.73725 1" />
      </material>
    </visual>
    <collision>
      <origin xyz="0 0 0" rpy="0 0 0" />
      <geometry>
        <mesh filename="package://model/omwr/meshes/wheel_link_4.STL" />
      </geometry>
    </collision>
  </link>
  <joint name="wheel_joint_4" type="continuous">
    <origin xyz="0 -0.078938 -0.0152" rpy="1.5708 0 0" />
    <parent link="base_link" />
    <child link="wheel_link_4" />
    <axis xyz="0 0 1" />
  </joint>
</robot>
